Workbook

Sheet Resumen
B2: PLAN DE ENTRENAMIENTO · MESOCICLO
B3: Tactical Biscuit Training · Bloque de 4 semanas
B5: DATOS DEL CLIENTE
B6: Cliente | G6: Entrenador
B7: Objetivo | G7: Robert
B8: Nivel
B9: Fecha de inicio | G9: Fin del mesociclo
B10: Días / semana | G10: =IF(C9="","",C9+27)
B11: Mesociclo nº
B13: PLANIFICACIÓN DE LAS 4 SEMANAS
B14: SEMANA | C14: FECHAS | D14: FASE | E14: RIR OBJETIVO | F14: VOLUMEN | G14: INTENSIDAD | H14: NOTAS
B15: Semana 1 | C15: =IF($C$9="","",TEXT($C$9+0,"dd/mm")&" – "&TEXT($C$9+6,"dd/mm")) | D15: Adaptación | E15: 3 | F15: Base | G15: Moderada
B16: Semana 2 | C16: =IF($C$9="","",TEXT($C$9+7,"dd/mm")&" – "&TEXT($C$9+13,"dd/mm")) | D16: Progresión | E16: 2 | F16: +1 serie en básicos | G16: Moderada-alta
B17: Semana 3 | C17: =IF($C$9="","",TEXT($C$9+14,"dd/mm")&" – "&TEXT($C$9+20,"dd/mm")) | D17: Intensificación | E17: 1 | F17: Mantener | G17: Alta
B18: Semana 4 | C18: =IF($C$9="","",TEXT($C$9+21,"dd/mm")&" – "&TEXT($C$9+27,"dd/mm")) | D18: Descarga | E18: 4 | F18: −40 % series | G18: Baja
B20: ESTRUCTURA SEMANAL
B21: SESIÓN | C21: DÍA DE LA SEMANA | D21: ENFOQUE / GRUPOS MUSCULARES | G21: DURACIÓN (min) | H21: MATERIAL / LUGAR
B22: Día A
B23: Día B
B24: Día C
B25: Día D
B27: CÓMO USAR ESTE PLAN
B28: Fondo AMARILLO | C28: Lo rellenas TÚ después de cada sesión: series, reps, kg y RIR reales, fecha y sensaciones.
B29: Fondo BLANCO | C29: Lo pauta el entrenador. No lo modifiques.
B30: RIR | C30: Repeticiones en reserva: cuántas reps más podrías haber hecho. 0 = al fallo · 1 = quedaba 1 · 3 = cómodo.
B31: Tempo (ej. 3-1-1-0) | C31: Segundos de bajada – pausa abajo – subida – pausa arriba.
B32: Progresión | C32: Si completas todas las reps con el RIR pautado, sube la carga la semana siguiente (2,5 – 5 %).
B33: ▶ Vídeo | C33: En cada día, pulsa «▶ Vídeo» junto al ejercicio para ver cómo se hace. También puedes buscar cualquier ejercicio en la hoja Biblioteca.
B34: Ejemplo de registro | C34: Sentadilla trasera · Pauta 4 × 8 · 60 kg · RIR 2 → Hecho: 4 series · 8-8-8-7 · 50-55-60-60 kg · RIR 1 (kg de cada serie separados por guiones y decimales con coma, p. ej. 25-27,5-30)

Sheet Día A
B2: PLAN DE ENTRENAMIENTO · DÍA A
B3: Tactical Biscuit Training
B5: Cliente | C5: =IF(Resumen!C6="","",Resumen!C6) | E5: Enfoque | F5: =IF(Resumen!D22="","",Resumen!D22) | J5: Día | K5: =IF(Resumen!C22="","",Resumen!C22)
B6: 🟨 Amarillo = lo rellenas TÚ · ⬜ Blanco = lo pauta el entrenador · RIR: 0 = al fallo · 1 = quedaba 1 rep · 3 = cómodo
B8: EJERCICIOS DEL DÍA
B9: Nº | C9: IMAGEN | D9: EJERCICIO | E9: GRUPO | F9: TEMPO | G9: DESCANSO | H9: INDICACIONES TÉCNICAS | M9: ▶ VÍDEO
B10: 1 | C10: 📷 | M10: =IF(D10="","",HYPERLINK(IF(IFERROR(INDEX(Biblioteca!$E$6:$E$150,MATCH(D10,Biblioteca!$C$6:$C$150,0))&"","")<>"",IFERROR(INDEX(Biblioteca!$E$6:$E$150,MATCH(D10,Biblioteca!$C$6:$C$150,0))&"",""),"https://www.youtube.com/results?search_query="&SUBSTITUTE(TRIM(D10)," ","+")&"+técnica"),IF(IFERROR(INDEX(Biblioteca!$E$6:$E$150,MATCH(D10,Biblioteca!$C$6:$C$150,0))&"","")<>"","▶ Mi vídeo","▶ Ver vídeo")))
B11: 2 | C11: 📷 | M11: =IF(D11="","",HYPERLINK(IF(IFERROR(INDEX(Biblioteca!$E$6:$E$150,MATCH(D11,Biblioteca!$C$6:$C$150,0))&"","")<>"",IFERROR(INDEX(Biblioteca!$E$6:$E$150,MATCH(D11,Biblioteca!$C$6:$C$150,0))&"",""),"https://www.youtube.com/results?search_query="&SUBSTITUTE(TRIM(D11)," ","+")&"+técnica"),IF(IFERROR(INDEX(Biblioteca!$E$6:$E$150,MATCH(D11,Biblioteca!$C$6:$C$150,0))&"","")<>"","▶ Mi vídeo","▶ Ver vídeo")))
B12: 3 | C12: 📷 | M12: =IF(D12="","",HYPERLINK(IF(IFERROR(INDEX(Biblioteca!$E$6:$E$150,MATCH(D12,Biblioteca!$C$6:$C$150,0))&"","")<>"",IFERROR(INDEX(Biblioteca!$E$6:$E$150,MATCH(D12,Biblioteca!$C$6:$C$150,0))&"",""),"https://www.youtube.com/results?search_query="&SUBSTITUTE(TRIM(D12)," ","+")&"+técnica"),IF(IFERROR(INDEX(Biblioteca!$E$6:$E$150,MATCH(D12,Biblioteca!$C$6:$C$150,0))&"","")<>"","▶ Mi vídeo","▶ Ver vídeo")))
B13: 4 | C13: 📷 | M13: =IF(D13="","",HYPERLINK(IF(IFERROR(INDEX(Biblioteca!$E$6:$E$150,MATCH(D13,Biblioteca!$C$6:$C$150,0))&"","")<>"",IFERROR(INDEX(Biblioteca!$E$6:$E$150,MATCH(D13,Biblioteca!$C$6:$C$150,0))&"",""),"https://www.youtube.com/results?search_query="&SUBSTITUTE(TRIM(D13)," ","+")&"+técnica"),IF(IFERROR(INDEX(Biblioteca!$E$6:$E$150,MATCH(D13,Biblioteca!$C$6:$C$150,0))&"","")<>"","▶ Mi vídeo","▶ Ver vídeo")))
B14: 5 | C14: 📷 | M14: =IF(D14="","",HYPERLINK(IF(IFERROR(INDEX(Biblioteca!$E$6:$E$150,MATCH(D14,Biblioteca!$C$6:$C$150,0))&"","")<>"",IFERROR(INDEX(Biblioteca!$E$6:$E$150,MATCH(D14,Biblioteca!$C$6:$C$150,0))&"",""),"https://www.youtube.com/results?search_query="&SUBSTITUTE(TRIM(D14)," ","+")&"+técnica"),IF(IFERROR(INDEX(Biblioteca!$E$6:$E$150,MATCH(D14,Biblioteca!$C$6:$C$150,0))&"","")<>"","▶ Mi vídeo","▶ Ver vídeo")))
B15: 6 | C15: 📷 | M15: =IF(D15="","",HYPERLINK(IF(IFERROR(INDEX(Biblioteca!$E$6:$E$150,MATCH(D15,Biblioteca!$C$6:$C$150,0))&"","")<>"",IFERROR(INDEX(Biblioteca!$E$6:$E$150,MATCH(D15,Biblioteca!$C$6:$C$150,0))&"",""),"https://www.youtube.com/results?search_query="&SUBSTITUTE(TRIM(D15)," ","+")&"+técnica"),IF(IFERROR(INDEX(Biblioteca!$E$6:$E$150,MATCH(D15,Biblioteca!$C$6:$C$150,0))&"","")<>"","▶ Mi vídeo","▶ Ver vídeo")))
B16: 7 | C16: 📷 | M16: =IF(D16="","",HYPERLINK(IF(IFERROR(INDEX(Biblioteca!$E$6:$E$150,MATCH(D16,Biblioteca!$C$6:$C$150,0))&"","")<>"",IFERROR(INDEX(Biblioteca!$E$6:$E$150,MATCH(D16,Biblioteca!$C$6:$C$150,0))&"",""),"https://www.youtube.com/results?search_query="&SUBSTITUTE(TRIM(D16)," ","+")&"+técnica"),IF(IFERROR(INDEX(Biblioteca!$E$6:$E$150,MATCH(D16,Biblioteca!$C$6:$C$150,0))&"","")<>"","▶ Mi vídeo","▶ Ver vídeo")))
B17: 8 | C17: 📷 | M17: =IF(D17="","",HYPERLINK(IF(IFERROR(INDEX(Biblioteca!$E$6:$E$150,MATCH(D17,Biblioteca!$C$6:$C$150,0))&"","")<>"",IFERROR(INDEX(Biblioteca!$E$6:$E$150,MATCH(D17,Biblioteca!$C$6:$C$150,0))&"",""),"https://www.youtube.com/results?search_query="&SUBSTITUTE(TRIM(D17)," ","+")&"+técnica"),IF(IFERROR(INDEX(Biblioteca!$E$6:$E$150,MATCH(D17,Biblioteca!$C$6:$C$150,0))&"","")<>"","▶ Mi vídeo","▶ Ver vídeo")))
B19: 🔥 CALENTAMIENTO PREVIO
B24: ="SEMANA 1 · "&UPPER(Resumen!D15)&" · RIR objetivo "&Resumen!E15&IF(Resumen!C15="",""," · "&Resumen!C15) -> SEMANA 1 · ADAPTACIÓN · RIR objetivo 3
B25: Fecha realizada: | E25: Duración (min): | H25: Sensación general (1-10):
E26: PROGRAMADO (entrenador) | I26: REALIZADO (rellenas tú)
B27: Nº | C27: EJERCICIO | E27: Series | F27: Reps | G27: Kg obj. | H27: RIR obj. | I27: Series | J27: Reps | K27: Kg | L27: RIR | M27: NOTAS / SENSACIÓN
B28: 1 | C28: =IF(D10="","",D10) | H28: =IF($C28="","",Resumen!$E$15)
B29: 2 | C29: =IF(D11="","",D11) | H29: =IF($C29="","",Resumen!$E$15)
B30: 3 | C30: =IF(D12="","",D12) | H30: =IF($C30="","",Resumen!$E$15)
B31: 4 | C31: =IF(D13="","",D13) | H31: =IF($C31="","",Resumen!$E$15)
B32: 5 | C32: =IF(D14="","",D14) | H32: =IF($C32="","",Resumen!$E$15)
B33: 6 | C33: =IF(D15="","",D15) | H33: =IF($C33="","",Resumen!$E$15)
B34: 7 | C34: =IF(D16="","",D16) | H34: =IF($C34="","",Resumen!$E$15)
B35: 8 | C35: =IF(D17="","",D17) | H35: =IF($C35="","",Resumen!$E$15)
B37: ="SEMANA 2 · "&UPPER(Resumen!D16)&" · RIR objetivo "&Resumen!E16&IF(Resumen!C16="",""," · "&Resumen!C16) -> SEMANA 2 · PROGRESIÓN · RIR objetivo 2
B38: Fecha realizada: | E38: Duración (min): | H38: Sensación general (1-10):
E39: PROGRAMADO (entrenador) | I39: REALIZADO (rellenas tú)
B40: Nº | C40: EJERCICIO | E40: Series | F40: Reps | G40: Kg obj. | H40: RIR obj. | I40: Series | J40: Reps | K40: Kg | L40: RIR | M40: NOTAS / SENSACIÓN
B41: 1 | C41: =IF(D10="","",D10) | E41: =IF(E28="","",E28) | F41: =IF(F28="","",F28) | H41: =IF($C41="","",Resumen!$E$16)
B42: 2 | C42: =IF(D11="","",D11) | E42: =IF(E29="","",E29) | F42: =IF(F29="","",F29) | H42: =IF($C42="","",Resumen!$E$16)
B43: 3 | C43: =IF(D12="","",D12) | E43: =IF(E30="","",E30) | F43: =IF(F30="","",F30) | H43: =IF($C43="","",Resumen!$E$16)
B44: 4 | C44: =IF(D13="","",D13) | E44: =IF(E31="","",E31) | F44: =IF(F31="","",F31) | H44: =IF($C44="","",Resumen!$E$16)
B45: 5 | C45: =IF(D14="","",D14) | E45: =IF(E32="","",E32) | F45: =IF(F32="","",F32) | H45: =IF($C45="","",Resumen!$E$16)
B46: 6 | C46: =IF(D15="","",D15) | E46: =IF(E33="","",E33) | F46: =IF(F33="","",F33) | H46: =IF($C46="","",Resumen!$E$16)
B47: 7 | C47: =IF(D16="","",D16) | E47: =IF(E34="","",E34) | F47: =IF(F34="","",F34) | H47: =IF($C47="","",Resumen!$E$16)
B48: 8 | C48: =IF(D17="","",D17) | E48: =IF(E35="","",E35) | F48: =IF(F35="","",F35) | H48: =IF($C48="","",Resumen!$E$16)
B50: ="SEMANA 3 · "&UPPER(Resumen!D17)&" · RIR objetivo "&Resumen!E17&IF(Resumen!C17="",""," · "&Resumen!C17) -> SEMANA 3 · INTENSIFICACIÓN · RIR objetivo 1
...

Sheet Día B
B2: PLAN DE ENTRENAMIENTO · DÍA B
B3: Tactical Biscuit Training
B5: Cliente | C5: =IF(Resumen!C6="","",Resumen!C6) | E5: Enfoque | F5: =IF(Resumen!D23="","",Resumen!D23) | J5: Día | K5: =IF(Resumen!C23="","",Resumen!C23)
B6: 🟨 Amarillo = lo rellenas TÚ · ⬜ Blanco = lo pauta el entrenador · RIR: 0 = al fallo · 1 = quedaba 1 rep · 3 = cómodo
B8: EJERCICIOS DEL DÍA
B9: Nº | C9: IMAGEN | D9: EJERCICIO | E9: GRUPO | F9: TEMPO | G9: DESCANSO | H9: INDICACIONES TÉCNICAS | M9: ▶ VÍDEO
B10: 1 | C10: 📷 | M10: =IF(D10="","",HYPERLINK(IF(IFERROR(INDEX(Biblioteca!$E$6:$E$150,MATCH(D10,Biblioteca!$C$6:$C$150,0))&"","")<>"",IFERROR(INDEX(Biblioteca!$E$6:$E$150,MATCH(D10,Biblioteca!$C$6:$C$150,0))&"",""),"https://www.youtube.com/results?search_query="&SUBSTITUTE(TRIM(D10)," ","+")&"+técnica"),IF(IFERROR(INDEX(Biblioteca!$E$6:$E$150,MATCH(D10,Biblioteca!$C$6:$C$150,0))&"","")<>"","▶ Mi vídeo","▶ Ver vídeo")))
B11: 2 | C11: 📷 | M11: =IF(D11="","",HYPERLINK(IF(IFERROR(INDEX(Biblioteca!$E$6:$E$150,MATCH(D11,Biblioteca!$C$6:$C$150,0))&"","")<>"",IFERROR(INDEX(Biblioteca!$E$6:$E$150,MATCH(D11,Biblioteca!$C$6:$C$150,0))&"",""),"https://www.youtube.com/results?search_query="&SUBSTITUTE(TRIM(D11)," ","+")&"+técnica"),IF(IFERROR(INDEX(Biblioteca!$E$6:$E$150,MATCH(D11,Biblioteca!$C$6:$C$150,0))&"","")<>"","▶ Mi vídeo","▶ Ver vídeo")))
B12: 3 | C12: 📷 | M12: =IF(D12="","",HYPERLINK(IF(IFERROR(INDEX(Biblioteca!$E$6:$E$150,MATCH(D12,Biblioteca!$C$6:$C$150,0))&"","")<>"",IFERROR(INDEX(Biblioteca!$E$6:$E$150,MATCH(D12,Biblioteca!$C$6:$C$150,0))&"",""),"https://www.youtube.com/results?search_query="&SUBSTITUTE(TRIM(D12)," ","+")&"+técnica"),IF(IFERROR(INDEX(Biblioteca!$E$6:$E$150,MATCH(D12,Biblioteca!$C$6:$C$150,0))&"","")<>"","▶ Mi vídeo","▶ Ver vídeo")))
B13: 4 | C13: 📷 | M13: =IF(D13="","",HYPERLINK(IF(IFERROR(INDEX(Biblioteca!$E$6:$E$150,MATCH(D13,Biblioteca!$C$6:$C$150,0))&"","")<>"",IFERROR(INDEX(Biblioteca!$E$6:$E$150,MATCH(D13,Biblioteca!$C$6:$C$150,0))&"",""),"https://www.youtube.com/results?search_query="&SUBSTITUTE(TRIM(D13)," ","+")&"+técnica"),IF(IFERROR(INDEX(Biblioteca!$E$6:$E$150,MATCH(D13,Biblioteca!$C$6:$C$150,0))&"","")<>"","▶ Mi vídeo","▶ Ver vídeo")))
B14: 5 | C14: 📷 | M14: =IF(D14="","",HYPERLINK(IF(IFERROR(INDEX(Biblioteca!$E$6:$E$150,MATCH(D14,Biblioteca!$C$6:$C$150,0))&"","")<>"",IFERROR(INDEX(Biblioteca!$E$6:$E$150,MATCH(D14,Biblioteca!$C$6:$C$150,0))&"",""),"https://www.youtube.com/results?search_query="&SUBSTITUTE(TRIM(D14)," ","+")&"+técnica"),IF(IFERROR(INDEX(Biblioteca!$E$6:$E$150,MATCH(D14,Biblioteca!$C$6:$C$150,0))&"","")<>"","▶ Mi vídeo","▶ Ver vídeo")))
B15: 6 | C15: 📷 | M15: =IF(D15="","",HYPERLINK(IF(IFERROR(INDEX(Biblioteca!$E$6:$E$150,MATCH(D15,Biblioteca!$C$6:$C$150,0))&"","")<>"",IFERROR(INDEX(Biblioteca!$E$6:$E$150,MATCH(D15,Biblioteca!$C$6:$C$150,0))&"",""),"https://www.youtube.com/results?search_query="&SUBSTITUTE(TRIM(D15)," ","+")&"+técnica"),IF(IFERROR(INDEX(Biblioteca!$E$6:$E$150,MATCH(D15,Biblioteca!$C$6:$C$150,0))&"","")<>"","▶ Mi vídeo","▶ Ver vídeo")))
B16: 7 | C16: 📷 | M16: =IF(D16="","",HYPERLINK(IF(IFERROR(INDEX(Biblioteca!$E$6:$E$150,MATCH(D16,Biblioteca!$C$6:$C$150,0))&"","")<>"",IFERROR(INDEX(Biblioteca!$E$6:$E$150,MATCH(D16,Biblioteca!$C$6:$C$150,0))&"",""),"https://www.youtube.com/results?search_query="&SUBSTITUTE(TRIM(D16)," ","+")&"+técnica"),IF(IFERROR(INDEX(Biblioteca!$E$6:$E$150,MATCH(D16,Biblioteca!$C$6:$C$150,0))&"","")<>"","▶ Mi vídeo","▶ Ver vídeo")))
B17: 8 | C17: 📷 | M17: =IF(D17="","",HYPERLINK(IF(IFERROR(INDEX(Biblioteca!$E$6:$E$150,MATCH(D17,Biblioteca!$C$6:$C$150,0))&"","")<>"",IFERROR(INDEX(Biblioteca!$E$6:$E$150,MATCH(D17,Biblioteca!$C$6:$C$150,0))&"",""),"https://www.youtube.com/results?search_query="&SUBSTITUTE(TRIM(D17)," ","+")&"+técnica"),IF(IFERROR(INDEX(Biblioteca!$E$6:$E$150,MATCH(D17,Biblioteca!$C$6:$C$150,0))&"","")<>"","▶ Mi vídeo","▶ Ver vídeo")))
B19: 🔥 CALENTAMIENTO PREVIO
B24: ="SEMANA 1 · "&UPPER(Resumen!D15)&" · RIR objetivo "&Resumen!E15&IF(Resumen!C15="",""," · "&Resumen!C15) -> SEMANA 1 · ADAPTACIÓN · RIR objetivo 3
B25: Fecha realizada: | E25: Duración (min): | H25: Sensación general (1-10):
E26: PROGRAMADO (entrenador) | I26: REALIZADO (rellenas tú)
B27: Nº | C27: EJERCICIO | E27: Series | F27: Reps | G27: Kg obj. | H27: RIR obj. | I27: Series | J27: Reps | K27: Kg | L27: RIR | M27: NOTAS / SENSACIÓN
B28: 1 | C28: =IF(D10="","",D10) | H28: =IF($C28="","",Resumen!$E$15)
B29: 2 | C29: =IF(D11="","",D11) | H29: =IF($C29="","",Resumen!$E$15)
B30: 3 | C30: =IF(D12="","",D12) | H30: =IF($C30="","",Resumen!$E$15)
B31: 4 | C31: =IF(D13="","",D13) | H31: =IF($C31="","",Resumen!$E$15)
B32: 5 | C32: =IF(D14="","",D14) | H32: =IF($C32="","",Resumen!$E$15)
B33: 6 | C33: =IF(D15="","",D15) | H33: =IF($C33="","",Resumen!$E$15)
B34: 7 | C34: =IF(D16="","",D16) | H34: =IF($C34="","",Resumen!$E$15)
B35: 8 | C35: =IF(D17="","",D17) | H35: =IF($C35="","",Resumen!$E$15)
B37: ="SEMANA 2 · "&UPPER(Resumen!D16)&" · RIR objetivo "&Resumen!E16&IF(Resumen!C16="",""," · "&Resumen!C16) -> SEMANA 2 · PROGRESIÓN · RIR objetivo 2
B38: Fecha realizada: | E38: Duración (min): | H38: Sensación general (1-10):
E39: PROGRAMADO (entrenador) | I39: REALIZADO (rellenas tú)
B40: Nº | C40: EJERCICIO | E40: Series | F40: Reps | G40: Kg obj. | H40: RIR obj. | I40: Series | J40: Reps | K40: Kg | L40: RIR | M40: NOTAS / SENSACIÓN
B41: 1 | C41: =IF(D10="","",D10) | E41: =IF(E28="","",E28) | F41: =IF(F28="","",F28) | H41: =IF($C41="","",Resumen!$E$16)
B42: 2 | C42: =IF(D11="","",D11) | E42: =IF(E29="","",E29) | F42: =IF(F29="","",F29) | H42: =IF($C42="","",Resumen!$E$16)
B43: 3 | C43: =IF(D12="","",D12) | E43: =IF(E30="","",E30) | F43: =IF(F30="","",F30) | H43: =IF($C43="","",Resumen!$E$16)
B44: 4 | C44: =IF(D13="","",D13) | E44: =IF(E31="","",E31) | F44: =IF(F31="","",F31) | H44: =IF($C44="","",Resumen!$E$16)
B45: 5 | C45: =IF(D14="","",D14) | E45: =IF(E32="","",E32) | F45: =IF(F32="","",F32) | H45: =IF($C45="","",Resumen!$E$16)
B46: 6 | C46: =IF(D15="","",D15) | E46: =IF(E33="","",E33) | F46: =IF(F33="","",F33) | H46: =IF($C46="","",Resumen!$E$16)
B47: 7 | C47: =IF(D16="","",D16) | E47: =IF(E34="","",E34) | F47: =IF(F34="","",F34) | H47: =IF($C47="","",Resumen!$E$16)
B48: 8 | C48: =IF(D17="","",D17) | E48: =IF(E35="","",E35) | F48: =IF(F35="","",F35) | H48: =IF($C48="","",Resumen!$E$16)
B50: ="SEMANA 3 · "&UPPER(Resumen!D17)&" · RIR objetivo "&Resumen!E17&IF(Resumen!C17="",""," · "&Resumen!C17) -> SEMANA 3 · INTENSIFICACIÓN · RIR objetivo 1
...

Sheet Día C
B2: PLAN DE ENTRENAMIENTO · DÍA C
B3: Tactical Biscuit Training
B5: Cliente | C5: =IF(Resumen!C6="","",Resumen!C6) | E5: Enfoque | F5: =IF(Resumen!D24="","",Resumen!D24) | J5: Día | K5: =IF(Resumen!C24="","",Resumen!C24)
B6: 🟨 Amarillo = lo rellenas TÚ · ⬜ Blanco = lo pauta el entrenador · RIR: 0 = al fallo · 1 = quedaba 1 rep · 3 = cómodo
B8: EJERCICIOS DEL DÍA
B9: Nº | C9: IMAGEN | D9: EJERCICIO | E9: GRUPO | F9: TEMPO | G9: DESCANSO | H9: INDICACIONES TÉCNICAS | M9: ▶ VÍDEO
B10: 1 | C10: 📷 | M10: =IF(D10="","",HYPERLINK(IF(IFERROR(INDEX(Biblioteca!$E$6:$E$150,MATCH(D10,Biblioteca!$C$6:$C$150,0))&"","")<>"",IFERROR(INDEX(Biblioteca!$E$6:$E$150,MATCH(D10,Biblioteca!$C$6:$C$150,0))&"",""),"https://www.youtube.com/results?search_query="&SUBSTITUTE(TRIM(D10)," ","+")&"+técnica"),IF(IFERROR(INDEX(Biblioteca!$E$6:$E$150,MATCH(D10,Biblioteca!$C$6:$C$150,0))&"","")<>"","▶ Mi vídeo","▶ Ver vídeo")))
B11: 2 | C11: 📷 | M11: =IF(D11="","",HYPERLINK(IF(IFERROR(INDEX(Biblioteca!$E$6:$E$150,MATCH(D11,Biblioteca!$C$6:$C$150,0))&"","")<>"",IFERROR(INDEX(Biblioteca!$E$6:$E$150,MATCH(D11,Biblioteca!$C$6:$C$150,0))&"",""),"https://www.youtube.com/results?search_query="&SUBSTITUTE(TRIM(D11)," ","+")&"+técnica"),IF(IFERROR(INDEX(Biblioteca!$E$6:$E$150,MATCH(D11,Biblioteca!$C$6:$C$150,0))&"","")<>"","▶ Mi vídeo","▶ Ver vídeo")))
B12: 3 | C12: 📷 | M12: =IF(D12="","",HYPERLINK(IF(IFERROR(INDEX(Biblioteca!$E$6:$E$150,MATCH(D12,Biblioteca!$C$6:$C$150,0))&"","")<>"",IFERROR(INDEX(Biblioteca!$E$6:$E$150,MATCH(D12,Biblioteca!$C$6:$C$150,0))&"",""),"https://www.youtube.com/results?search_query="&SUBSTITUTE(TRIM(D12)," ","+")&"+técnica"),IF(IFERROR(INDEX(Biblioteca!$E$6:$E$150,MATCH(D12,Biblioteca!$C$6:$C$150,0))&"","")<>"","▶ Mi vídeo","▶ Ver vídeo")))
B13: 4 | C13: 📷 | M13: =IF(D13="","",HYPERLINK(IF(IFERROR(INDEX(Biblioteca!$E$6:$E$150,MATCH(D13,Biblioteca!$C$6:$C$150,0))&"","")<>"",IFERROR(INDEX(Biblioteca!$E$6:$E$150,MATCH(D13,Biblioteca!$C$6:$C$150,0))&"",""),"https://www.youtube.com/results?search_query="&SUBSTITUTE(TRIM(D13)," ","+")&"+técnica"),IF(IFERROR(INDEX(Biblioteca!$E$6:$E$150,MATCH(D13,Biblioteca!$C$6:$C$150,0))&"","")<>"","▶ Mi vídeo","▶ Ver vídeo")))
B14: 5 | C14: 📷 | M14: =IF(D14="","",HYPERLINK(IF(IFERROR(INDEX(Biblioteca!$E$6:$E$150,MATCH(D14,Biblioteca!$C$6:$C$150,0))&"","")<>"",IFERROR(INDEX(Biblioteca!$E$6:$E$150,MATCH(D14,Biblioteca!$C$6:$C$150,0))&"",""),"https://www.youtube.com/results?search_query="&SUBSTITUTE(TRIM(D14)," ","+")&"+técnica"),IF(IFERROR(INDEX(Biblioteca!$E$6:$E$150,MATCH(D14,Biblioteca!$C$6:$C$150,0))&"","")<>"","▶ Mi vídeo","▶ Ver vídeo")))
B15: 6 | C15: 📷 | M15: =IF(D15="","",HYPERLINK(IF(IFERROR(INDEX(Biblioteca!$E$6:$E$150,MATCH(D15,Biblioteca!$C$6:$C$150,0))&"","")<>"",IFERROR(INDEX(Biblioteca!$E$6:$E$150,MATCH(D15,Biblioteca!$C$6:$C$150,0))&"",""),"https://www.youtube.com/results?search_query="&SUBSTITUTE(TRIM(D15)," ","+")&"+técnica"),IF(IFERROR(INDEX(Biblioteca!$E$6:$E$150,MATCH(D15,Biblioteca!$C$6:$C$150,0))&"","")<>"","▶ Mi vídeo","▶ Ver vídeo")))
B16: 7 | C16: 📷 | M16: =IF(D16="","",HYPERLINK(IF(IFERROR(INDEX(Biblioteca!$E$6:$E$150,MATCH(D16,Biblioteca!$C$6:$C$150,0))&"","")<>"",IFERROR(INDEX(Biblioteca!$E$6:$E$150,MATCH(D16,Biblioteca!$C$6:$C$150,0))&"",""),"https://www.youtube.com/results?search_query="&SUBSTITUTE(TRIM(D16)," ","+")&"+técnica"),IF(IFERROR(INDEX(Biblioteca!$E$6:$E$150,MATCH(D16,Biblioteca!$C$6:$C$150,0))&"","")<>"","▶ Mi vídeo","▶ Ver vídeo")))
B17: 8 | C17: 📷 | M17: =IF(D17="","",HYPERLINK(IF(IFERROR(INDEX(Biblioteca!$E$6:$E$150,MATCH(D17,Biblioteca!$C$6:$C$150,0))&"","")<>"",IFERROR(INDEX(Biblioteca!$E$6:$E$150,MATCH(D17,Biblioteca!$C$6:$C$150,0))&"",""),"https://www.youtube.com/results?search_query="&SUBSTITUTE(TRIM(D17)," ","+")&"+técnica"),IF(IFERROR(INDEX(Biblioteca!$E$6:$E$150,MATCH(D17,Biblioteca!$C$6:$C$150,0))&"","")<>"","▶ Mi vídeo","▶ Ver vídeo")))
B19: 🔥 CALENTAMIENTO PREVIO
B24: ="SEMANA 1 · "&UPPER(Resumen!D15)&" · RIR objetivo "&Resumen!E15&IF(Resumen!C15="",""," · "&Resumen!C15) -> SEMANA 1 · ADAPTACIÓN · RIR objetivo 3
B25: Fecha realizada: | E25: Duración (min): | H25: Sensación general (1-10):
E26: PROGRAMADO (entrenador) | I26: REALIZADO (rellenas tú)
B27: Nº | C27: EJERCICIO | E27: Series | F27: Reps | G27: Kg obj. | H27: RIR obj. | I27: Series | J27: Reps | K27: Kg | L27: RIR | M27: NOTAS / SENSACIÓN
B28: 1 | C28: =IF(D10="","",D10) | H28: =IF($C28="","",Resumen!$E$15)
B29: 2 | C29: =IF(D11="","",D11) | H29: =IF($C29="","",Resumen!$E$15)
B30: 3 | C30: =IF(D12="","",D12) | H30: =IF($C30="","",Resumen!$E$15)
B31: 4 | C31: =IF(D13="","",D13) | H31: =IF($C31="","",Resumen!$E$15)
B32: 5 | C32: =IF(D14="","",D14) | H32: =IF($C32="","",Resumen!$E$15)
B33: 6 | C33: =IF(D15="","",D15) | H33: =IF($C33="","",Resumen!$E$15)
B34: 7 | C34: =IF(D16="","",D16) | H34: =IF($C34="","",Resumen!$E$15)
B35: 8 | C35: =IF(D17="","",D17) | H35: =IF($C35="","",Resumen!$E$15)
B37: ="SEMANA 2 · "&UPPER(Resumen!D16)&" · RIR objetivo "&Resumen!E16&IF(Resumen!C16="",""," · "&Resumen!C16) -> SEMANA 2 · PROGRESIÓN · RIR objetivo 2
B38: Fecha realizada: | E38: Duración (min): | H38: Sensación general (1-10):
E39: PROGRAMADO (entrenador) | I39: REALIZADO (rellenas tú)
B40: Nº | C40: EJERCICIO | E40: Series | F40: Reps | G40: Kg obj. | H40: RIR obj. | I40: Series | J40: Reps | K40: Kg | L40: RIR | M40: NOTAS / SENSACIÓN
B41: 1 | C41: =IF(D10="","",D10) | E41: =IF(E28="","",E28) | F41: =IF(F28="","",F28) | H41: =IF($C41="","",Resumen!$E$16)
B42: 2 | C42: =IF(D11="","",D11) | E42: =IF(E29="","",E29) | F42: =IF(F29="","",F29) | H42: =IF($C42="","",Resumen!$E$16)
B43: 3 | C43: =IF(D12="","",D12) | E43: =IF(E30="","",E30) | F43: =IF(F30="","",F30) | H43: =IF($C43="","",Resumen!$E$16)
B44: 4 | C44: =IF(D13="","",D13) | E44: =IF(E31="","",E31) | F44: =IF(F31="","",F31) | H44: =IF($C44="","",Resumen!$E$16)
B45: 5 | C45: =IF(D14="","",D14) | E45: =IF(E32="","",E32) | F45: =IF(F32="","",F32) | H45: =IF($C45="","",Resumen!$E$16)
B46: 6 | C46: =IF(D15="","",D15) | E46: =IF(E33="","",E33) | F46: =IF(F33="","",F33) | H46: =IF($C46="","",Resumen!$E$16)
B47: 7 | C47: =IF(D16="","",D16) | E47: =IF(E34="","",E34) | F47: =IF(F34="","",F34) | H47: =IF($C47="","",Resumen!$E$16)
B48: 8 | C48: =IF(D17="","",D17) | E48: =IF(E35="","",E35) | F48: =IF(F35="","",F35) | H48: =IF($C48="","",Resumen!$E$16)
B50: ="SEMANA 3 · "&UPPER(Resumen!D17)&" · RIR objetivo "&Resumen!E17&IF(Resumen!C17="",""," · "&Resumen!C17) -> SEMANA 3 · INTENSIFICACIÓN · RIR objetivo 1
...

Sheet Día D
B2: PLAN DE ENTRENAMIENTO · DÍA D
B3: Tactical Biscuit Training
B5: Cliente | C5: =IF(Resumen!C6="","",Resumen!C6) | E5: Enfoque | F5: =IF(Resumen!D25="","",Resumen!D25) | J5: Día | K5: =IF(Resumen!C25="","",Resumen!C25)
B6: 🟨 Amarillo = lo rellenas TÚ · ⬜ Blanco = lo pauta el entrenador · RIR: 0 = al fallo · 1 = quedaba 1 rep · 3 = cómodo
B8: EJERCICIOS DEL DÍA
B9: Nº | C9: IMAGEN | D9: EJERCICIO | E9: GRUPO | F9: TEMPO | G9: DESCANSO | H9: INDICACIONES TÉCNICAS | M9: ▶ VÍDEO
B10: 1 | C10: 📷 | M10: =IF(D10="","",HYPERLINK(IF(IFERROR(INDEX(Biblioteca!$E$6:$E$150,MATCH(D10,Biblioteca!$C$6:$C$150,0))&"","")<>"",IFERROR(INDEX(Biblioteca!$E$6:$E$150,MATCH(D10,Biblioteca!$C$6:$C$150,0))&"",""),"https://www.youtube.com/results?search_query="&SUBSTITUTE(TRIM(D10)," ","+")&"+técnica"),IF(IFERROR(INDEX(Biblioteca!$E$6:$E$150,MATCH(D10,Biblioteca!$C$6:$C$150,0))&"","")<>"","▶ Mi vídeo","▶ Ver vídeo")))
B11: 2 | C11: 📷 | M11: =IF(D11="","",HYPERLINK(IF(IFERROR(INDEX(Biblioteca!$E$6:$E$150,MATCH(D11,Biblioteca!$C$6:$C$150,0))&"","")<>"",IFERROR(INDEX(Biblioteca!$E$6:$E$150,MATCH(D11,Biblioteca!$C$6:$C$150,0))&"",""),"https://www.youtube.com/results?search_query="&SUBSTITUTE(TRIM(D11)," ","+")&"+técnica"),IF(IFERROR(INDEX(Biblioteca!$E$6:$E$150,MATCH(D11,Biblioteca!$C$6:$C$150,0))&"","")<>"","▶ Mi vídeo","▶ Ver vídeo")))
B12: 3 | C12: 📷 | M12: =IF(D12="","",HYPERLINK(IF(IFERROR(INDEX(Biblioteca!$E$6:$E$150,MATCH(D12,Biblioteca!$C$6:$C$150,0))&"","")<>"",IFERROR(INDEX(Biblioteca!$E$6:$E$150,MATCH(D12,Biblioteca!$C$6:$C$150,0))&"",""),"https://www.youtube.com/results?search_query="&SUBSTITUTE(TRIM(D12)," ","+")&"+técnica"),IF(IFERROR(INDEX(Biblioteca!$E$6:$E$150,MATCH(D12,Biblioteca!$C$6:$C$150,0))&"","")<>"","▶ Mi vídeo","▶ Ver vídeo")))
B13: 4 | C13: 📷 | M13: =IF(D13="","",HYPERLINK(IF(IFERROR(INDEX(Biblioteca!$E$6:$E$150,MATCH(D13,Biblioteca!$C$6:$C$150,0))&"","")<>"",IFERROR(INDEX(Biblioteca!$E$6:$E$150,MATCH(D13,Biblioteca!$C$6:$C$150,0))&"",""),"https://www.youtube.com/results?search_query="&SUBSTITUTE(TRIM(D13)," ","+")&"+técnica"),IF(IFERROR(INDEX(Biblioteca!$E$6:$E$150,MATCH(D13,Biblioteca!$C$6:$C$150,0))&"","")<>"","▶ Mi vídeo","▶ Ver vídeo")))
B14: 5 | C14: 📷 | M14: =IF(D14="","",HYPERLINK(IF(IFERROR(INDEX(Biblioteca!$E$6:$E$150,MATCH(D14,Biblioteca!$C$6:$C$150,0))&"","")<>"",IFERROR(INDEX(Biblioteca!$E$6:$E$150,MATCH(D14,Biblioteca!$C$6:$C$150,0))&"",""),"https://www.youtube.com/results?search_query="&SUBSTITUTE(TRIM(D14)," ","+")&"+técnica"),IF(IFERROR(INDEX(Biblioteca!$E$6:$E$150,MATCH(D14,Biblioteca!$C$6:$C$150,0))&"","")<>"","▶ Mi vídeo","▶ Ver vídeo")))
B15: 6 | C15: 📷 | M15: =IF(D15="","",HYPERLINK(IF(IFERROR(INDEX(Biblioteca!$E$6:$E$150,MATCH(D15,Biblioteca!$C$6:$C$150,0))&"","")<>"",IFERROR(INDEX(Biblioteca!$E$6:$E$150,MATCH(D15,Biblioteca!$C$6:$C$150,0))&"",""),"https://www.youtube.com/results?search_query="&SUBSTITUTE(TRIM(D15)," ","+")&"+técnica"),IF(IFERROR(INDEX(Biblioteca!$E$6:$E$150,MATCH(D15,Biblioteca!$C$6:$C$150,0))&"","")<>"","▶ Mi vídeo","▶ Ver vídeo")))
B16: 7 | C16: 📷 | M16: =IF(D16="","",HYPERLINK(IF(IFERROR(INDEX(Biblioteca!$E$6:$E$150,MATCH(D16,Biblioteca!$C$6:$C$150,0))&"","")<>"",IFERROR(INDEX(Biblioteca!$E$6:$E$150,MATCH(D16,Biblioteca!$C$6:$C$150,0))&"",""),"https://www.youtube.com/results?search_query="&SUBSTITUTE(TRIM(D16)," ","+")&"+técnica"),IF(IFERROR(INDEX(Biblioteca!$E$6:$E$150,MATCH(D16,Biblioteca!$C$6:$C$150,0))&"","")<>"","▶ Mi vídeo","▶ Ver vídeo")))
B17: 8 | C17: 📷 | M17: =IF(D17="","",HYPERLINK(IF(IFERROR(INDEX(Biblioteca!$E$6:$E$150,MATCH(D17,Biblioteca!$C$6:$C$150,0))&"","")<>"",IFERROR(INDEX(Biblioteca!$E$6:$E$150,MATCH(D17,Biblioteca!$C$6:$C$150,0))&"",""),"https://www.youtube.com/results?search_query="&SUBSTITUTE(TRIM(D17)," ","+")&"+técnica"),IF(IFERROR(INDEX(Biblioteca!$E$6:$E$150,MATCH(D17,Biblioteca!$C$6:$C$150,0))&"","")<>"","▶ Mi vídeo","▶ Ver vídeo")))
B19: 🔥 CALENTAMIENTO PREVIO
B24: ="SEMANA 1 · "&UPPER(Resumen!D15)&" · RIR objetivo "&Resumen!E15&IF(Resumen!C15="",""," · "&Resumen!C15) -> SEMANA 1 · ADAPTACIÓN · RIR objetivo 3
B25: Fecha realizada: | E25: Duración (min): | H25: Sensación general (1-10):
E26: PROGRAMADO (entrenador) | I26: REALIZADO (rellenas tú)
B27: Nº | C27: EJERCICIO | E27: Series | F27: Reps | G27: Kg obj. | H27: RIR obj. | I27: Series | J27: Reps | K27: Kg | L27: RIR | M27: NOTAS / SENSACIÓN
B28: 1 | C28: =IF(D10="","",D10) | H28: =IF($C28="","",Resumen!$E$15)
B29: 2 | C29: =IF(D11="","",D11) | H29: =IF($C29="","",Resumen!$E$15)
B30: 3 | C30: =IF(D12="","",D12) | H30: =IF($C30="","",Resumen!$E$15)
B31: 4 | C31: =IF(D13="","",D13) | H31: =IF($C31="","",Resumen!$E$15)
B32: 5 | C32: =IF(D14="","",D14) | H32: =IF($C32="","",Resumen!$E$15)
B33: 6 | C33: =IF(D15="","",D15) | H33: =IF($C33="","",Resumen!$E$15)
B34: 7 | C34: =IF(D16="","",D16) | H34: =IF($C34="","",Resumen!$E$15)
B35: 8 | C35: =IF(D17="","",D17) | H35: =IF($C35="","",Resumen!$E$15)
B37: ="SEMANA 2 · "&UPPER(Resumen!D16)&" · RIR objetivo "&Resumen!E16&IF(Resumen!C16="",""," · "&Resumen!C16) -> SEMANA 2 · PROGRESIÓN · RIR objetivo 2
B38: Fecha realizada: | E38: Duración (min): | H38: Sensación general (1-10):
E39: PROGRAMADO (entrenador) | I39: REALIZADO (rellenas tú)
B40: Nº | C40: EJERCICIO | E40: Series | F40: Reps | G40: Kg obj. | H40: RIR obj. | I40: Series | J40: Reps | K40: Kg | L40: RIR | M40: NOTAS / SENSACIÓN
B41: 1 | C41: =IF(D10="","",D10) | E41: =IF(E28="","",E28) | F41: =IF(F28="","",F28) | H41: =IF($C41="","",Resumen!$E$16)
B42: 2 | C42: =IF(D11="","",D11) | E42: =IF(E29="","",E29) | F42: =IF(F29="","",F29) | H42: =IF($C42="","",Resumen!$E$16)
B43: 3 | C43: =IF(D12="","",D12) | E43: =IF(E30="","",E30) | F43: =IF(F30="","",F30) | H43: =IF($C43="","",Resumen!$E$16)
B44: 4 | C44: =IF(D13="","",D13) | E44: =IF(E31="","",E31) | F44: =IF(F31="","",F31) | H44: =IF($C44="","",Resumen!$E$16)
B45: 5 | C45: =IF(D14="","",D14) | E45: =IF(E32="","",E32) | F45: =IF(F32="","",F32) | H45: =IF($C45="","",Resumen!$E$16)
B46: 6 | C46: =IF(D15="","",D15) | E46: =IF(E33="","",E33) | F46: =IF(F33="","",F33) | H46: =IF($C46="","",Resumen!$E$16)
B47: 7 | C47: =IF(D16="","",D16) | E47: =IF(E34="","",E34) | F47: =IF(F34="","",F34) | H47: =IF($C47="","",Resumen!$E$16)
B48: 8 | C48: =IF(D17="","",D17) | E48: =IF(E35="","",E35) | F48: =IF(F35="","",F35) | H48: =IF($C48="","",Resumen!$E$16)
B50: ="SEMANA 3 · "&UPPER(Resumen!D17)&" · RIR objetivo "&Resumen!E17&IF(Resumen!C17="",""," · "&Resumen!C17) -> SEMANA 3 · INTENSIFICACIÓN · RIR objetivo 1
...

Sheet Check-in semanal
B2: CHECK-IN SEMANAL
B3: Tactical Biscuit Training · Rellénalo cada domingo y envíaselo a tu entrenador
B5: SEMANA | C5: FECHA | D5: PESO MEDIO (kg) | E5: PASOS / DÍA | F5: SUEÑO (h) | G5: ENERGÍA (1-10) | H5: ESTRÉS (1-10) | I5: HAMBRE (1-10) | J5: DIETA CUMPLIDA (%) | K5: SESIONES HECHAS | L5: COMENTARIOS / DIFICULTADES
B6: Semana 1 | K6: =COUNT('Día A'!D25,'Día B'!D25,'Día C'!D25,'Día D'!D25)&" / "&IF(Resumen!$C$10="",4,Resumen!$C$10) -> 0 / 4
B7: Semana 2 | K7: =COUNT('Día A'!D38,'Día B'!D38,'Día C'!D38,'Día D'!D38)&" / "&IF(Resumen!$C$10="",4,Resumen!$C$10) -> 0 / 4
B8: Semana 3 | K8: =COUNT('Día A'!D51,'Día B'!D51,'Día C'!D51,'Día D'!D51)&" / "&IF(Resumen!$C$10="",4,Resumen!$C$10) -> 0 / 4
B9: Semana 4 | K9: =COUNT('Día A'!D64,'Día B'!D64,'Día C'!D64,'Día D'!D64)&" / "&IF(Resumen!$C$10="",4,Resumen!$C$10) -> 0 / 4
B10: Media | D10: =IF(COUNT(D6:D9)=0,"",AVERAGE(D6:D9)) | E10: =IF(COUNT(E6:E9)=0,"",AVERAGE(E6:E9)) | F10: =IF(COUNT(F6:F9)=0,"",AVERAGE(F6:F9)) | G10: =IF(COUNT(G6:G9)=0,"",AVERAGE(G6:G9)) | H10: =IF(COUNT(H6:H9)=0,"",AVERAGE(H6:H9)) | I10: =IF(COUNT(I6:I9)=0,"",AVERAGE(I6:I9)) | J10: =IF(COUNT(J6:J9)=0,"",AVERAGE(J6:J9))
B12: Peso medio: pésate 3-4 mañanas en ayunas y anota la media. Dieta cumplida: % aproximado de comidas que seguiste según el plan. «Sesiones hechas» se calcula sola con las fechas que anotas en cada día.

Sheet Biblioteca
B2: BIBLIOTECA DE EJERCICIOS
B3: Tactical Biscuit Training · Busca un ejercicio, mira su imagen y pulsa «▶ Ver vídeo» para ver cómo se hace
B4: 🔎 Busca un ejercicio: | E4: Escribe una palabra (ej.: remo, sentadilla, glúteo) y se marcan en amarillo
B5: GRUPO | C5: EJERCICIO | D5: MATERIAL | E5: ENLACE A TU VÍDEO (opcional) | F5: ▶ VÍDEO | G5: IMAGEN
B6: Pecho | C6: Press banca con barra | D6: Barra | F6: =IF(C6="","",IF(E6<>"",HYPERLINK(E6,"▶ Mi vídeo"),HYPERLINK("https://www.youtube.com/results?search_query="&SUBSTITUTE(TRIM(C6)," ","+")&"+técnica","▶ Ver vídeo"))) -> ▶ Ver vídeo
B7: Pecho | C7: Press inclinado con mancuernas | D7: Mancuernas | F7: =IF(C7="","",IF(E7<>"",HYPERLINK(E7,"▶ Mi vídeo"),HYPERLINK("https://www.youtube.com/results?search_query="&SUBSTITUTE(TRIM(C7)," ","+")&"+técnica","▶ Ver vídeo"))) -> ▶ Ver vídeo
B8: Pecho | C8: Press banca con mancuernas | D8: Mancuernas | F8: =IF(C8="","",IF(E8<>"",HYPERLINK(E8,"▶ Mi vídeo"),HYPERLINK("https://www.youtube.com/results?search_query="&SUBSTITUTE(TRIM(C8)," ","+")&"+técnica","▶ Ver vídeo"))) -> ▶ Ver vídeo
B9: Pecho | C9: Aperturas en polea (cruce) | D9: Polea | F9: =IF(C9="","",IF(E9<>"",HYPERLINK(E9,"▶ Mi vídeo"),HYPERLINK("https://www.youtube.com/results?search_query="&SUBSTITUTE(TRIM(C9)," ","+")&"+técnica","▶ Ver vídeo"))) -> ▶ Ver vídeo
B10: Pecho | C10: Press en máquina | D10: Máquina | F10: =IF(C10="","",IF(E10<>"",HYPERLINK(E10,"▶ Mi vídeo"),HYPERLINK("https://www.youtube.com/results?search_query="&SUBSTITUTE(TRIM(C10)," ","+")&"+técnica","▶ Ver vídeo"))) -> ▶ Ver vídeo
B11: Pecho | C11: Fondos en paralelas | D11: Peso corporal | F11: =IF(C11="","",IF(E11<>"",HYPERLINK(E11,"▶ Mi vídeo"),HYPERLINK("https://www.youtube.com/results?search_query="&SUBSTITUTE(TRIM(C11)," ","+")&"+técnica","▶ Ver vídeo"))) -> ▶ Ver vídeo
B12: Pecho | C12: Flexiones | D12: Peso corporal | F12: =IF(C12="","",IF(E12<>"",HYPERLINK(E12,"▶ Mi vídeo"),HYPERLINK("https://www.youtube.com/results?search_query="&SUBSTITUTE(TRIM(C12)," ","+")&"+técnica","▶ Ver vídeo"))) -> ▶ Ver vídeo
B13: Espalda | C13: Dominadas | D13: Barra fija | F13: =IF(C13="","",IF(E13<>"",HYPERLINK(E13,"▶ Mi vídeo"),HYPERLINK("https://www.youtube.com/results?search_query="&SUBSTITUTE(TRIM(C13)," ","+")&"+técnica","▶ Ver vídeo"))) -> ▶ Ver vídeo
B14: Espalda | C14: Jalón al pecho | D14: Polea | F14: =IF(C14="","",IF(E14<>"",HYPERLINK(E14,"▶ Mi vídeo"),HYPERLINK("https://www.youtube.com/results?search_query="&SUBSTITUTE(TRIM(C14)," ","+")&"+técnica","▶ Ver vídeo"))) -> ▶ Ver vídeo
B15: Espalda | C15: Remo con barra | D15: Barra | F15: =IF(C15="","",IF(E15<>"",HYPERLINK(E15,"▶ Mi vídeo"),HYPERLINK("https://www.youtube.com/results?search_query="&SUBSTITUTE(TRIM(C15)," ","+")&"+técnica","▶ Ver vídeo"))) -> ▶ Ver vídeo
B16: Espalda | C16: Remo con mancuerna a una mano | D16: Mancuernas | F16: =IF(C16="","",IF(E16<>"",HYPERLINK(E16,"▶ Mi vídeo"),HYPERLINK("https://www.youtube.com/results?search_query="&SUBSTITUTE(TRIM(C16)," ","+")&"+técnica","▶ Ver vídeo"))) -> ▶ Ver vídeo
B17: Espalda | C17: Remo en polea baja | D17: Polea | F17: =IF(C17="","",IF(E17<>"",HYPERLINK(E17,"▶ Mi vídeo"),HYPERLINK("https://www.youtube.com/results?search_query="&SUBSTITUTE(TRIM(C17)," ","+")&"+técnica","▶ Ver vídeo"))) -> ▶ Ver vídeo
... B70: Cardio / Metabólico | C70: Burpees | D70: Peso corporal | F70: =IF(C70="","",IF(E70<>"",HYPERLINK(E70,"▶ Mi vídeo"),HYPERLINK("https://www.youtube.com/results?search_query="&SUBSTITUTE(TRIM(C70)," ","+")&"+técnica","▶ Ver vídeo"))) -> ▶ Ver vídeo
F71: =IF(C71="","",IF(E71<>"",HYPERLINK(E71,"▶ Mi vídeo"),HYPERLINK("https://www.youtube.com/results?search_query="&SUBSTITUTE(TRIM(C71)," ","+")&"+técnica","▶ Ver vídeo")))
F72: =IF(C72="","",IF(E72<>"",HYPERLINK(E72,"▶ Mi vídeo"),HYPERLINK("https://www.youtube.com/results?search_query="&SUBSTITUTE(TRIM(C72)," ","+")&"+técnica","▶ Ver vídeo")))
F73: =IF(C73="","",IF(E73<>"",HYPERLINK(E73,"▶ Mi vídeo"),HYPERLINK("https://www.youtube.com/results?search_query="&SUBSTITUTE(TRIM(C73)," ","+")&"+técnica","▶ Ver vídeo")))
F74: =IF(C74="","",IF(E74<>"",HYPERLINK(E74,"▶ Mi vídeo"),HYPERLINK("https://www.youtube.com/results?search_query="&SUBSTITUTE(TRIM(C74)," ","+")&"+técnica","▶ Ver vídeo")))
F75: =IF(C75="","",IF(E75<>"",HYPERLINK(E75,"▶ Mi vídeo"),HYPERLINK("https://www.youtube.com/results?search_query="&SUBSTITUTE(TRIM(C75)," ","+")&"+técnica","▶ Ver vídeo")))
F76: =IF(C76="","",IF(E76<>"",HYPERLINK(E76,"▶ Mi vídeo"),HYPERLINK("https://www.youtube.com/results?search_query="&SUBSTITUTE(TRIM(C76)," ","+")&"+técnica","▶ Ver vídeo")))
F77: =IF(C77="","",IF(E77<>"",HYPERLINK(E77,"▶ Mi vídeo"),HYPERLINK("https://www.youtube.com/results?search_query="&SUBSTITUTE(TRIM(C77)," ","+")&"+técnica","▶ Ver vídeo")))
F78: =IF(C78="","",IF(E78<>"",HYPERLINK(E78,"▶ Mi vídeo"),HYPERLINK("https://www.youtube.com/results?search_query="&SUBSTITUTE(TRIM(C78)," ","+")&"+técnica","▶ Ver vídeo")))
F79: =IF(C79="","",IF(E79<>"",HYPERLINK(E79,"▶ Mi vídeo"),HYPERLINK("https://www.youtube.com/results?search_query="&SUBSTITUTE(TRIM(C79)," ","+")&"+técnica","▶ Ver vídeo")))
F80: =IF(C80="","",IF(E80<>"",HYPERLINK(E80,"▶ Mi vídeo"),HYPERLINK("https://www.youtube.com/results?search_query="&SUBSTITUTE(TRIM(C80)," ","+")&"+técnica","▶ Ver vídeo")))
F81: =IF(C81="","",IF(E81<>"",HYPERLINK(E81,"▶ Mi vídeo"),HYPERLINK("https://www.youtube.com/results?search_query="&SUBSTITUTE(TRIM(C81)," ","+")&"+técnica","▶ Ver vídeo")))
F82: =IF(C82="","",IF(E82<>"",HYPERLINK(E82,"▶ Mi vídeo"),HYPERLINK("https://www.youtube.com/results?search_query="&SUBSTITUTE(TRIM(C82)," ","+")&"+técnica","▶ Ver vídeo")))
... F150: =IF(C150="","",IF(E150<>"",HYPERLINK(E150,"▶ Mi vídeo"),HYPERLINK("https://www.youtube.com/results?search_query="&SUBSTITUTE(TRIM(C150)," ","+")&"+técnica","▶ Ver vídeo")))
B152: Los ejercicios sin enlace propio abren una búsqueda en YouTube. Cuando tengas tu vídeo, pega el enlace en la columna «Enlace a tu vídeo» y el botón pasará a abrir el tuyo (también en las hojas de cada día). Imagen: cópiala y pégala en la columna IMAGEN de cada día. Puedes añadir ejercicios nuevos al final de la lista.
